[2025-03-27T00:56:29.590+0000] {local_task_job_runner.py:123} INFO - ::group::Pre task execution logs
[2025-03-27T00:56:29.598+0000] {taskinstance.py:2612} INFO - Dependencies all met for dep_context=non-requeueable deps ti=<TaskInstance: user_session_data.ETL manual__2025-03-27T00:56:28.034005+00:00 [queued]>
[2025-03-27T00:56:29.603+0000] {taskinstance.py:2612} INFO - Dependencies all met for dep_context=requeueable deps ti=<TaskInstance: user_session_data.ETL manual__2025-03-27T00:56:28.034005+00:00 [queued]>
[2025-03-27T00:56:29.603+0000] {taskinstance.py:2865} INFO - Starting attempt 1 of 1
[2025-03-27T00:56:29.611+0000] {taskinstance.py:2888} INFO - Executing <Task(_PythonDecoratedOperator): ETL> on 2025-03-27 00:56:28.034005+00:00
[2025-03-27T00:56:29.616+0000] {logging_mixin.py:190} WARNING - /home/***/.local/lib/python3.12/site-packages/***/task/task_runner/standard_task_runner.py:70 DeprecationWarning: This process (pid=406) is multi-threaded, use of fork() may lead to deadlocks in the child.
[2025-03-27T00:56:29.616+0000] {standard_task_runner.py:72} INFO - Started process 415 to run task
[2025-03-27T00:56:29.616+0000] {standard_task_runner.py:104} INFO - Running: ['***', 'tasks', 'run', 'user_session_data', 'ETL', 'manual__2025-03-27T00:56:28.034005+00:00', '--job-id', '67', '--raw', '--subdir', 'DAGS_FOLDER/data226_hwk6.py', '--cfg-path', '/tmp/tmpqf7fk5gp']
[2025-03-27T00:56:29.617+0000] {standard_task_runner.py:105} INFO - Job 67: Subtask ETL
[2025-03-27T00:56:29.644+0000] {task_command.py:467} INFO - Running <TaskInstance: user_session_data.ETL manual__2025-03-27T00:56:28.034005+00:00 [running]> on host be8ca46e30d3
[2025-03-27T00:56:29.687+0000] {taskinstance.py:3131} INFO - Exporting env vars: AIRFLOW_CTX_DAG_OWNER='***' AIRFLOW_CTX_DAG_ID='user_session_data' AIRFLOW_CTX_TASK_ID='ETL' AIRFLOW_CTX_EXECUTION_DATE='2025-03-27T00:56:28.034005+00:00' AIRFLOW_CTX_TRY_NUMBER='1' AIRFLOW_CTX_DAG_RUN_ID='manual__2025-03-27T00:56:28.034005+00:00'
[2025-03-27T00:56:29.688+0000] {taskinstance.py:731} INFO - ::endgroup::
[2025-03-27T00:56:29.695+0000] {base.py:84} INFO - Retrieving connection 'snowflake_conn2'
[2025-03-27T00:56:29.696+0000] {connection.py:413} INFO - Snowflake Connector for Python Version: 3.12.1, Python Version: 3.12.5, Platform: Linux-5.15.167.4-microsoft-standard-WSL2-x86_64-with-glibc2.36
[2025-03-27T00:56:29.697+0000] {connection.py:1196} INFO - Connecting to GLOBAL Snowflake domain
[2025-03-27T00:56:29.697+0000] {connection.py:1277} INFO - This connection is in OCSP Fail Open Mode. TLS Certificates would be checked for validity and revocation status. Any other Certificate Revocation related exceptions or OCSP Responder failures would be disregarded in favor of connectivity.
[2025-03-27T00:56:30.355+0000] {cursor.py:1156} INFO - Number of results in first chunk: 1
[2025-03-27T00:56:30.471+0000] {cursor.py:1156} INFO - Number of results in first chunk: 1
[2025-03-27T00:56:30.579+0000] {cursor.py:1156} INFO - Number of results in first chunk: 1
[2025-03-27T00:56:30.715+0000] {cursor.py:1156} INFO - Number of results in first chunk: 1
[2025-03-27T00:56:30.715+0000] {logging_mixin.py:190} INFO - SnowflakeCursor.execute() got an unexpected keyword argument 'multi'
[2025-03-27T00:56:30.716+0000] {taskinstance.py:3310} ERROR - Task failed with exception
Traceback (most recent call last):
  File "/home/airflow/.local/lib/python3.12/site-packages/airflow/models/taskinstance.py", line 767, in _execute_task
    result = _execute_callable(context=context, **execute_callable_kwargs)
             ^^^^^^^^^^^^^^^^^^^^^^^^^^^^^^^^^^^^^^^^^^^^^^^^^^^^^^^^^^^^^
  File "/home/airflow/.local/lib/python3.12/site-packages/airflow/models/taskinstance.py", line 733, in _execute_callable
    return ExecutionCallableRunner(
           ^^^^^^^^^^^^^^^^^^^^^^^^
  File "/home/airflow/.local/lib/python3.12/site-packages/airflow/utils/operator_helpers.py", line 252, in run
    return self.func(*args, **kwargs)
           ^^^^^^^^^^^^^^^^^^^^^^^^^^
  File "/home/airflow/.local/lib/python3.12/site-packages/airflow/models/baseoperator.py", line 406, in wrapper
    return func(self, *args, **kwargs)
           ^^^^^^^^^^^^^^^^^^^^^^^^^^^
  File "/home/airflow/.local/lib/python3.12/site-packages/airflow/decorators/base.py", line 266, in execute
    return_value = super().execute(context)
                   ^^^^^^^^^^^^^^^^^^^^^^^^
  File "/home/airflow/.local/lib/python3.12/site-packages/airflow/models/baseoperator.py", line 406, in wrapper
    return func(self, *args, **kwargs)
           ^^^^^^^^^^^^^^^^^^^^^^^^^^^
  File "/home/airflow/.local/lib/python3.12/site-packages/airflow/operators/python.py", line 238, in execute
    return_value = self.execute_callable()
                   ^^^^^^^^^^^^^^^^^^^^^^^
  File "/home/airflow/.local/lib/python3.12/site-packages/airflow/operators/python.py", line 256, in execute_callable
    return runner.run(*self.op_args, **self.op_kwargs)
           ^^^^^^^^^^^^^^^^^^^^^^^^^^^^^^^^^^^^^^^^^^^
  File "/home/airflow/.local/lib/python3.12/site-packages/airflow/utils/operator_helpers.py", line 252, in run
    return self.func(*args, **kwargs)
           ^^^^^^^^^^^^^^^^^^^^^^^^^^
  File "/opt/airflow/dags/data226_hwk6.py", line 53, in ETL
    raise e
  File "/opt/airflow/dags/data226_hwk6.py", line 48, in ETL
    cur.execute(sql, multi=True)
TypeError: SnowflakeCursor.execute() got an unexpected keyword argument 'multi'
[2025-03-27T00:56:30.723+0000] {taskinstance.py:1225} INFO - Marking task as FAILED. dag_id=user_session_data, task_id=ETL, run_id=manual__2025-03-27T00:56:28.034005+00:00, execution_date=20250327T005628, start_date=20250327T005629, end_date=20250327T005630
[2025-03-27T00:56:30.732+0000] {taskinstance.py:340} INFO - ::group::Post task execution logs
[2025-03-27T00:56:30.732+0000] {standard_task_runner.py:124} ERROR - Failed to execute job 67 for task ETL (SnowflakeCursor.execute() got an unexpected keyword argument 'multi'; 415)
Traceback (most recent call last):
  File "/home/airflow/.local/lib/python3.12/site-packages/airflow/task/task_runner/standard_task_runner.py", line 117, in _start_by_fork
    ret = args.func(args, dag=self.dag)
          ^^^^^^^^^^^^^^^^^^^^^^^^^^^^^
  File "/home/airflow/.local/lib/python3.12/site-packages/airflow/cli/cli_config.py", line 49, in command
    return func(*args, **kwargs)
           ^^^^^^^^^^^^^^^^^^^^^
  File "/home/airflow/.local/lib/python3.12/site-packages/airflow/utils/cli.py", line 115, in wrapper
    return f(*args, **kwargs)
           ^^^^^^^^^^^^^^^^^^
  File "/home/airflow/.local/lib/python3.12/site-packages/airflow/cli/commands/task_command.py", line 483, in task_run
    task_return_code = _run_task_by_selected_method(args, _dag, ti)
                       ^^^^^^^^^^^^^^^^^^^^^^^^^^^^^^^^^^^^^^^^^^^^
  File "/home/airflow/.local/lib/python3.12/site-packages/airflow/cli/commands/task_command.py", line 256, in _run_task_by_selected_method
    return _run_raw_task(args, ti)
           ^^^^^^^^^^^^^^^^^^^^^^^
  File "/home/airflow/.local/lib/python3.12/site-packages/airflow/cli/commands/task_command.py", line 341, in _run_raw_task
    return ti._run_raw_task(
           ^^^^^^^^^^^^^^^^^
  File "/home/airflow/.local/lib/python3.12/site-packages/airflow/utils/session.py", line 97, in wrapper
    return func(*args, session=session, **kwargs)
           ^^^^^^^^^^^^^^^^^^^^^^^^^^^^^^^^^^^^^^
  File "/home/airflow/.local/lib/python3.12/site-packages/airflow/models/taskinstance.py", line 3004, in _run_raw_task
    return _run_raw_task(
           ^^^^^^^^^^^^^^
  File "/home/airflow/.local/lib/python3.12/site-packages/airflow/models/taskinstance.py", line 273, in _run_raw_task
    TaskInstance._execute_task_with_callbacks(
  File "/home/airflow/.local/lib/python3.12/site-packages/airflow/models/taskinstance.py", line 3158, in _execute_task_with_callbacks
    result = self._execute_task(context, task_orig)
             ^^^^^^^^^^^^^^^^^^^^^^^^^^^^^^^^^^^^^^
  File "/home/airflow/.local/lib/python3.12/site-packages/airflow/models/taskinstance.py", line 3182, in _execute_task
    return _execute_task(self, context, task_orig)
           ^^^^^^^^^^^^^^^^^^^^^^^^^^^^^^^^^^^^^^^
  File "/home/airflow/.local/lib/python3.12/site-packages/airflow/models/taskinstance.py", line 767, in _execute_task
    result = _execute_callable(context=context, **execute_callable_kwargs)
             ^^^^^^^^^^^^^^^^^^^^^^^^^^^^^^^^^^^^^^^^^^^^^^^^^^^^^^^^^^^^^
  File "/home/airflow/.local/lib/python3.12/site-packages/airflow/models/taskinstance.py", line 733, in _execute_callable
    return ExecutionCallableRunner(
           ^^^^^^^^^^^^^^^^^^^^^^^^
  File "/home/airflow/.local/lib/python3.12/site-packages/airflow/utils/operator_helpers.py", line 252, in run
    return self.func(*args, **kwargs)
           ^^^^^^^^^^^^^^^^^^^^^^^^^^
  File "/home/airflow/.local/lib/python3.12/site-packages/airflow/models/baseoperator.py", line 406, in wrapper
    return func(self, *args, **kwargs)
           ^^^^^^^^^^^^^^^^^^^^^^^^^^^
  File "/home/airflow/.local/lib/python3.12/site-packages/airflow/decorators/base.py", line 266, in execute
    return_value = super().execute(context)
                   ^^^^^^^^^^^^^^^^^^^^^^^^
  File "/home/airflow/.local/lib/python3.12/site-packages/airflow/models/baseoperator.py", line 406, in wrapper
    return func(self, *args, **kwargs)
           ^^^^^^^^^^^^^^^^^^^^^^^^^^^
  File "/home/airflow/.local/lib/python3.12/site-packages/airflow/operators/python.py", line 238, in execute
    return_value = self.execute_callable()
                   ^^^^^^^^^^^^^^^^^^^^^^^
  File "/home/airflow/.local/lib/python3.12/site-packages/airflow/operators/python.py", line 256, in execute_callable
    return runner.run(*self.op_args, **self.op_kwargs)
           ^^^^^^^^^^^^^^^^^^^^^^^^^^^^^^^^^^^^^^^^^^^
  File "/home/airflow/.local/lib/python3.12/site-packages/airflow/utils/operator_helpers.py", line 252, in run
    return self.func(*args, **kwargs)
           ^^^^^^^^^^^^^^^^^^^^^^^^^^
  File "/opt/airflow/dags/data226_hwk6.py", line 53, in ETL
    raise e
  File "/opt/airflow/dags/data226_hwk6.py", line 48, in ETL
    cur.execute(sql, multi=True)
TypeError: SnowflakeCursor.execute() got an unexpected keyword argument 'multi'
[2025-03-27T00:56:30.753+0000] {local_task_job_runner.py:266} INFO - Task exited with return code 1
[2025-03-27T00:56:30.761+0000] {taskinstance.py:3900} INFO - 0 downstream tasks scheduled from follow-on schedule check
[2025-03-27T00:56:30.765+0000] {local_task_job_runner.py:245} INFO - ::endgroup::
