[2025-03-27T01:13:51.215+0000] {local_task_job_runner.py:123} INFO - ::group::Pre task execution logs
[2025-03-27T01:13:51.226+0000] {taskinstance.py:2612} INFO - Dependencies all met for dep_context=non-requeueable deps ti=<TaskInstance: BuildELT_CTAS.run_ctas scheduled__2025-03-25T02:45:00+00:00 [queued]>
[2025-03-27T01:13:51.230+0000] {taskinstance.py:2612} INFO - Dependencies all met for dep_context=requeueable deps ti=<TaskInstance: BuildELT_CTAS.run_ctas scheduled__2025-03-25T02:45:00+00:00 [queued]>
[2025-03-27T01:13:51.230+0000] {taskinstance.py:2865} INFO - Starting attempt 1 of 1
[2025-03-27T01:13:51.240+0000] {taskinstance.py:2888} INFO - Executing <Task(_PythonDecoratedOperator): run_ctas> on 2025-03-25 02:45:00+00:00
[2025-03-27T01:13:51.246+0000] {logging_mixin.py:190} WARNING - /home/***/.local/lib/python3.12/site-packages/***/task/task_runner/standard_task_runner.py:70 DeprecationWarning: This process (pid=300) is multi-threaded, use of fork() may lead to deadlocks in the child.
[2025-03-27T01:13:51.245+0000] {standard_task_runner.py:104} INFO - Running: ['***', 'tasks', 'run', 'BuildELT_CTAS', 'run_ctas', 'scheduled__2025-03-25T02:45:00+00:00', '--job-id', '70', '--raw', '--subdir', 'DAGS_FOLDER/data226_hwk6_ELT.py', '--cfg-path', '/tmp/tmpcyihki56']
[2025-03-27T01:13:51.247+0000] {standard_task_runner.py:72} INFO - Started process 303 to run task
[2025-03-27T01:13:51.247+0000] {standard_task_runner.py:105} INFO - Job 70: Subtask run_ctas
[2025-03-27T01:13:51.277+0000] {task_command.py:467} INFO - Running <TaskInstance: BuildELT_CTAS.run_ctas scheduled__2025-03-25T02:45:00+00:00 [running]> on host ef75a37f18d3
[2025-03-27T01:13:51.324+0000] {taskinstance.py:3131} INFO - Exporting env vars: AIRFLOW_CTX_DAG_OWNER='***' AIRFLOW_CTX_DAG_ID='BuildELT_CTAS' AIRFLOW_CTX_TASK_ID='run_ctas' AIRFLOW_CTX_EXECUTION_DATE='2025-03-25T02:45:00+00:00' AIRFLOW_CTX_TRY_NUMBER='1' AIRFLOW_CTX_DAG_RUN_ID='scheduled__2025-03-25T02:45:00+00:00'
[2025-03-27T01:13:51.324+0000] {taskinstance.py:731} INFO - ::endgroup::
[2025-03-27T01:13:51.326+0000] {data226_hwk6_ELT.py:34} INFO - session_summary
[2025-03-27T01:13:51.327+0000] {data226_hwk6_ELT.py:35} INFO - SELECT u.*, s.ts
    FROM USER_DB_DOG.raw.user_session_channel u
    JOIN USER_DB_DOG.raw.session_timestamp s ON u.sessionId=s.sessionId
    
[2025-03-27T01:13:51.334+0000] {base.py:84} INFO - Retrieving connection 'snowflake_conn2'
[2025-03-27T01:13:51.335+0000] {connection.py:413} INFO - Snowflake Connector for Python Version: 3.12.1, Python Version: 3.12.5, Platform: Linux-5.15.167.4-microsoft-standard-WSL2-x86_64-with-glibc2.36
[2025-03-27T01:13:51.335+0000] {connection.py:1196} INFO - Connecting to GLOBAL Snowflake domain
[2025-03-27T01:13:51.336+0000] {connection.py:1277} INFO - This connection is in OCSP Fail Open Mode. TLS Certificates would be checked for validity and revocation status. Any other Certificate Revocation related exceptions or OCSP Responder failures would be disregarded in favor of connectivity.
[2025-03-27T01:13:52.257+0000] {data226_hwk6_ELT.py:41} INFO - CREATE OR REPLACE TABLE USER_DB_DOG.analytics.temp_session_summary AS SELECT u.*, s.ts
    FROM USER_DB_DOG.raw.user_session_channel u
    JOIN USER_DB_DOG.raw.session_timestamp s ON u.sessionId=s.sessionId
    
[2025-03-27T01:13:54.992+0000] {cursor.py:1156} INFO - Number of results in first chunk: 1
[2025-03-27T01:13:54.992+0000] {logging_mixin.py:190} INFO - 
              SELECT sessionId, COUNT(1) AS cnt 
              FROM USER_DB_DOG.analytics.temp_session_summary
              GROUP BY 1
              ORDER BY 2 DESC
              LIMIT 1
[2025-03-27T01:13:55.429+0000] {cursor.py:1156} INFO - Number of results in first chunk: 1
[2025-03-27T01:13:55.430+0000] {logging_mixin.py:190} INFO - ('7cdace91c487558e27ce54df7cdb299c', 1) 1
[2025-03-27T01:13:56.361+0000] {taskinstance.py:3310} ERROR - Task failed with exception
Traceback (most recent call last):
  File "/home/airflow/.local/lib/python3.12/site-packages/airflow/models/taskinstance.py", line 767, in _execute_task
    result = _execute_callable(context=context, **execute_callable_kwargs)
             ^^^^^^^^^^^^^^^^^^^^^^^^^^^^^^^^^^^^^^^^^^^^^^^^^^^^^^^^^^^^^
  File "/home/airflow/.local/lib/python3.12/site-packages/airflow/models/taskinstance.py", line 733, in _execute_callable
    return ExecutionCallableRunner(
           ^^^^^^^^^^^^^^^^^^^^^^^^
  File "/home/airflow/.local/lib/python3.12/site-packages/airflow/utils/operator_helpers.py", line 252, in run
    return self.func(*args, **kwargs)
           ^^^^^^^^^^^^^^^^^^^^^^^^^^
  File "/home/airflow/.local/lib/python3.12/site-packages/airflow/models/baseoperator.py", line 406, in wrapper
    return func(self, *args, **kwargs)
           ^^^^^^^^^^^^^^^^^^^^^^^^^^^
  File "/home/airflow/.local/lib/python3.12/site-packages/airflow/decorators/base.py", line 266, in execute
    return_value = super().execute(context)
                   ^^^^^^^^^^^^^^^^^^^^^^^^
  File "/home/airflow/.local/lib/python3.12/site-packages/airflow/models/baseoperator.py", line 406, in wrapper
    return func(self, *args, **kwargs)
           ^^^^^^^^^^^^^^^^^^^^^^^^^^^
  File "/home/airflow/.local/lib/python3.12/site-packages/airflow/operators/python.py", line 238, in execute
    return_value = self.execute_callable()
                   ^^^^^^^^^^^^^^^^^^^^^^^
  File "/home/airflow/.local/lib/python3.12/site-packages/airflow/operators/python.py", line 256, in execute_callable
    return runner.run(*self.op_args, **self.op_kwargs)
           ^^^^^^^^^^^^^^^^^^^^^^^^^^^^^^^^^^^^^^^^^^^
  File "/home/airflow/.local/lib/python3.12/site-packages/airflow/utils/operator_helpers.py", line 252, in run
    return self.func(*args, **kwargs)
           ^^^^^^^^^^^^^^^^^^^^^^^^^^
  File "/opt/airflow/dags/data226_hwk6_ELT.py", line 63, in run_ctas
    cur.execute(main_table_creation_if_not_exists_sql)
  File "/home/airflow/.local/lib/python3.12/site-packages/snowflake/connector/cursor.py", line 1087, in execute
    Error.errorhandler_wrapper(self.connection, self, error_class, errvalue)
  File "/home/airflow/.local/lib/python3.12/site-packages/snowflake/connector/errors.py", line 284, in errorhandler_wrapper
    handed_over = Error.hand_to_other_handler(
                  ^^^^^^^^^^^^^^^^^^^^^^^^^^^^
  File "/home/airflow/.local/lib/python3.12/site-packages/snowflake/connector/errors.py", line 339, in hand_to_other_handler
    cursor.errorhandler(connection, cursor, error_class, error_value)
  File "/home/airflow/.local/lib/python3.12/site-packages/snowflake/connector/errors.py", line 215, in default_errorhandler
    raise error_class(
snowflake.connector.errors.ProgrammingError: 090015 (00000): 01bb4709-0104-cd23-0004-59ff000f476e: SESSION_SUMMARY already exists, statement succeeded.
[2025-03-27T01:13:56.367+0000] {taskinstance.py:1225} INFO - Marking task as FAILED. dag_id=BuildELT_CTAS, task_id=run_ctas, run_id=scheduled__2025-03-25T02:45:00+00:00, execution_date=20250325T024500, start_date=20250327T011351, end_date=20250327T011356
[2025-03-27T01:13:56.375+0000] {taskinstance.py:340} INFO - ::group::Post task execution logs
[2025-03-27T01:13:56.375+0000] {standard_task_runner.py:124} ERROR - Failed to execute job 70 for task run_ctas (090015 (00000): 01bb4709-0104-cd23-0004-59ff000f476e: SESSION_SUMMARY already exists, statement succeeded.; 303)
Traceback (most recent call last):
  File "/home/airflow/.local/lib/python3.12/site-packages/airflow/task/task_runner/standard_task_runner.py", line 117, in _start_by_fork
    ret = args.func(args, dag=self.dag)
          ^^^^^^^^^^^^^^^^^^^^^^^^^^^^^
  File "/home/airflow/.local/lib/python3.12/site-packages/airflow/cli/cli_config.py", line 49, in command
    return func(*args, **kwargs)
           ^^^^^^^^^^^^^^^^^^^^^
  File "/home/airflow/.local/lib/python3.12/site-packages/airflow/utils/cli.py", line 115, in wrapper
    return f(*args, **kwargs)
           ^^^^^^^^^^^^^^^^^^
  File "/home/airflow/.local/lib/python3.12/site-packages/airflow/cli/commands/task_command.py", line 483, in task_run
    task_return_code = _run_task_by_selected_method(args, _dag, ti)
                       ^^^^^^^^^^^^^^^^^^^^^^^^^^^^^^^^^^^^^^^^^^^^
  File "/home/airflow/.local/lib/python3.12/site-packages/airflow/cli/commands/task_command.py", line 256, in _run_task_by_selected_method
    return _run_raw_task(args, ti)
           ^^^^^^^^^^^^^^^^^^^^^^^
  File "/home/airflow/.local/lib/python3.12/site-packages/airflow/cli/commands/task_command.py", line 341, in _run_raw_task
    return ti._run_raw_task(
           ^^^^^^^^^^^^^^^^^
  File "/home/airflow/.local/lib/python3.12/site-packages/airflow/utils/session.py", line 97, in wrapper
    return func(*args, session=session, **kwargs)
           ^^^^^^^^^^^^^^^^^^^^^^^^^^^^^^^^^^^^^^
  File "/home/airflow/.local/lib/python3.12/site-packages/airflow/models/taskinstance.py", line 3004, in _run_raw_task
    return _run_raw_task(
           ^^^^^^^^^^^^^^
  File "/home/airflow/.local/lib/python3.12/site-packages/airflow/models/taskinstance.py", line 273, in _run_raw_task
    TaskInstance._execute_task_with_callbacks(
  File "/home/airflow/.local/lib/python3.12/site-packages/airflow/models/taskinstance.py", line 3158, in _execute_task_with_callbacks
    result = self._execute_task(context, task_orig)
             ^^^^^^^^^^^^^^^^^^^^^^^^^^^^^^^^^^^^^^
  File "/home/airflow/.local/lib/python3.12/site-packages/airflow/models/taskinstance.py", line 3182, in _execute_task
    return _execute_task(self, context, task_orig)
           ^^^^^^^^^^^^^^^^^^^^^^^^^^^^^^^^^^^^^^^
  File "/home/airflow/.local/lib/python3.12/site-packages/airflow/models/taskinstance.py", line 767, in _execute_task
    result = _execute_callable(context=context, **execute_callable_kwargs)
             ^^^^^^^^^^^^^^^^^^^^^^^^^^^^^^^^^^^^^^^^^^^^^^^^^^^^^^^^^^^^^
  File "/home/airflow/.local/lib/python3.12/site-packages/airflow/models/taskinstance.py", line 733, in _execute_callable
    return ExecutionCallableRunner(
           ^^^^^^^^^^^^^^^^^^^^^^^^
  File "/home/airflow/.local/lib/python3.12/site-packages/airflow/utils/operator_helpers.py", line 252, in run
    return self.func(*args, **kwargs)
           ^^^^^^^^^^^^^^^^^^^^^^^^^^
  File "/home/airflow/.local/lib/python3.12/site-packages/airflow/models/baseoperator.py", line 406, in wrapper
    return func(self, *args, **kwargs)
           ^^^^^^^^^^^^^^^^^^^^^^^^^^^
  File "/home/airflow/.local/lib/python3.12/site-packages/airflow/decorators/base.py", line 266, in execute
    return_value = super().execute(context)
                   ^^^^^^^^^^^^^^^^^^^^^^^^
  File "/home/airflow/.local/lib/python3.12/site-packages/airflow/models/baseoperator.py", line 406, in wrapper
    return func(self, *args, **kwargs)
           ^^^^^^^^^^^^^^^^^^^^^^^^^^^
  File "/home/airflow/.local/lib/python3.12/site-packages/airflow/operators/python.py", line 238, in execute
    return_value = self.execute_callable()
                   ^^^^^^^^^^^^^^^^^^^^^^^
  File "/home/airflow/.local/lib/python3.12/site-packages/airflow/operators/python.py", line 256, in execute_callable
    return runner.run(*self.op_args, **self.op_kwargs)
           ^^^^^^^^^^^^^^^^^^^^^^^^^^^^^^^^^^^^^^^^^^^
  File "/home/airflow/.local/lib/python3.12/site-packages/airflow/utils/operator_helpers.py", line 252, in run
    return self.func(*args, **kwargs)
           ^^^^^^^^^^^^^^^^^^^^^^^^^^
  File "/opt/airflow/dags/data226_hwk6_ELT.py", line 63, in run_ctas
    cur.execute(main_table_creation_if_not_exists_sql)
  File "/home/airflow/.local/lib/python3.12/site-packages/snowflake/connector/cursor.py", line 1087, in execute
    Error.errorhandler_wrapper(self.connection, self, error_class, errvalue)
  File "/home/airflow/.local/lib/python3.12/site-packages/snowflake/connector/errors.py", line 284, in errorhandler_wrapper
    handed_over = Error.hand_to_other_handler(
                  ^^^^^^^^^^^^^^^^^^^^^^^^^^^^
  File "/home/airflow/.local/lib/python3.12/site-packages/snowflake/connector/errors.py", line 339, in hand_to_other_handler
    cursor.errorhandler(connection, cursor, error_class, error_value)
  File "/home/airflow/.local/lib/python3.12/site-packages/snowflake/connector/errors.py", line 215, in default_errorhandler
    raise error_class(
snowflake.connector.errors.ProgrammingError: 090015 (00000): 01bb4709-0104-cd23-0004-59ff000f476e: SESSION_SUMMARY already exists, statement succeeded.
[2025-03-27T01:13:56.420+0000] {local_task_job_runner.py:266} INFO - Task exited with return code 1
[2025-03-27T01:13:56.428+0000] {taskinstance.py:3900} INFO - 0 downstream tasks scheduled from follow-on schedule check
[2025-03-27T01:13:56.430+0000] {local_task_job_runner.py:245} INFO - ::endgroup::
